## 第 16 章. React 中的通用错误处理

我们都希望自己的应用程序稳定、完美运行，并且能处理所有可能的边缘情况，不是吗？但遗憾的现实是，我们都是人类（至少我是这么假设的），我们都会犯错，而且不存在没有 bug 的代码。无论我们多么小心，或者编写了多少自动化测试，总会有某个时候出现严重的问题。从用户体验的角度来看，重要的是要预测到这些严重问题，尽可能定位问题，并以优雅的方式处理，直到问题真正得到修复。

在最后一章中，让我们来看看 React 中的错误处理：

- 当错误发生时，我们可以做些什么。
- 不同错误捕获方法的注意事项是什么。
- 如何缓解这些问题。

## 为什么我们要在 React 中捕获错误

但首先要搞清楚：为什么在 React 中拥有某种错误捕获解决方案至关重要呢？

答案很简单：从版本 16 开始，如果在 React 生命周期中抛出的错误没有得到处理，将会导致整个应用程序卸载。在此之前，即使组件格式错误或行为异常，它们仍会保留在屏幕上。现在，UI 中某个无关紧要的部分，甚至是你无法控制的某个外部库中一个不幸的未捕获错误，都可能会破坏整个页面，让所有用户看到一个空白屏幕。

前端开发人员从未拥有过如此大的破坏力！

## 回顾如何在 JavaScript 中捕获错误

在普通 JavaScript 中捕获这些讨厌的意外时，工具非常简单明了。

我们有常用的 try/catch [40] 语句，它或多或少不言自明：尝试执行某些操作，如果失败了，就捕获错误并采取措施进行缓解：

```jsx
try {
  // 如果我们做了错误的事情，这可能会抛出一个错误
  doSomething();
} catch (e) {
  // 如果发生错误，捕获它并在不停止应用程序的情况下对其进行处理
  // 比如将这个错误发送到某个日志服务
}
```

相同的语法也适用于异步函数：

```jsx
try {
  await fetch("/bla-bla");
} catch (e) {
  // oh no, the fetch failed! We should do something about it!
}
```

或者，如果我们使用传统的 Promise，我们有专门针对它们的 catch 方法。因此，如果我们使用基于 Promise 的 API 重写之前的 fetch 示例，它将如下所示：

```jsx
fetch("/bla-bla")
  .then((result) => {
    // 如果 Promise 执行成功，结果将在这里
    // 我们可以对其进行一些有用的操作
  })
  .catch((e) => {
    // 哦不，请求失败了！我们应该对此做点什么！
  });
```

这是相同的概念，只是实现方式略有不同，因此在本章的其余部分，我将对所有错误都使用 try/catch 语法。

## React 中的简单 try/catch：使用方法和注意事项

当捕获到错误时，我们需要对其进行处理，对吧？那么，除了将错误记录到某个地方之外，我们具体还能做些什么呢？或者更准确地说：我们能为用户做些什么呢？仅仅让用户看到一个空白屏幕或损坏的界面，显然不太友好。

最明显和直观的答案是，在等待修复错误的同时渲染一些内容。幸运的是，我们可以在 `catch` 语句中做任何想做的事情，包括设置状态。所以我们可以这样做：

```jsx
const SomeComponent = () => {
  const [hasError, setHasError] = useState(false);
  useEffect(() => {
    try {
      // 执行一些操作，比如获取数据
    } catch (e) {
      // 哦不！获取数据失败了，我们没有数据可渲染！
      setHasError(true);
    }
  });
  // 获取数据期间发生了某些事情，让我们渲染一个不错的错误屏幕
  if (hasError) return <SomeErrorScreen />;

  // 一切正常，数据已获取，开始渲染
  return <SomeComponentContent {...datasomething} />;
};
```

我们正在尝试发送一个 fetch 请求，如果请求失败，就设置错误状态。如果错误状态为 true，我们会渲染一个包含额外信息（如支持联系电话）的错误屏幕。

这种方法非常直接，对于像捕获失败的 fetch 请求这类简单、可预测且范围较窄的用例非常有效。

但如果你想捕获组件中可能发生的所有错误，就会面临一些挑战和严重的限制。

### 限制 1：使用 useEffect 钩子时会遇到问题。

如果我们用 try/catch 包裹 useEffect，它根本不会起作用：

```jsx
try {
  useEffect(() => {
    throw new Error("Hulk smash!");
  }, []);
} catch (e) {
  // useEffect 抛出了错误，但这里的代码永远不会被调用
}
```

这种情况的发生是因为 `useEffect` 会在渲染完成后异步调用，因此从 `try/catch` 的角度来看，一切都成功执行了。这和我们在第 15 章“数据获取和竞态条件”中讨论的任何 Promise 情况一样：如果我们不等待结果，JavaScript 会继续执行其他任务，当 Promise 完成时再返回来，然后才执行 `useEffect` 内部（或 Promise 的 `then` 方法）的代码。到那时，`try/catch` 块早已执行完毕。

为了捕获 `useEffect` 内部的错误，`try/catch` 也应该放在其内部：

```jsx
useEffect(() => {
  try {
    throw new Error("Hulk smash!");
  } catch (e) {
    // this one will be caught
  }
}, []);
```

> 交互式示例和完整代码
> https://advanced-react.com/examples/16/01

这适用于任何使用 `useEffect` 的钩子，或者实际上任何异步操作。因此，你不能用一个 `try/catch` 块包裹所有内容，而必须将其拆分为多个块：每个钩子一个。

### 限制 2：子组件。

`try/catch` 无法捕获子组件内部发生的任何错误。你不能这样做：

```jsx
const Component = () => {
  let child;
  try {
    child = <Child />;
  } catch (e) {
    // 对于捕获子组件内部的错误无效，不会被触发
  }
  return child;
};
```

或者甚至这样：

```jsx
const Component = () => {
  try {
    return <Child />;
  } catch (e) {
    // 对于捕获子组件内部的错误仍然无效，不会被触发
  }
};
```

> 交互式示例和完整代码
> https://advanced-react.com/examples/16/02

出现这种情况是因为当我们编写 `<Child />` 时，实际上并没有渲染这个组件。我们正在做的是创建一个组件元素，它不过是组件的定义而已。它只是一个包含必要信息（如组件类型和属性）的对象，这些信息稍后会被 React 本身使用，React 才会真正触发该组件的渲染。我们在第 2 章“元素、作为属性的子元素和重新渲染”、第 3 章“将元素作为属性时的配置问题”和第 6 章“深入探究差异比较和协调”中详细讨论过这个问题。

并且渲染会在 `try/catch` 块成功执行之后发生，这和 Promise 以及 `useEffect` 钩子的情况完全一样。

### 限制 3：在渲染期间设置状态是不可行的

如果你试图在 `useEffect` 和各种回调之外（即组件渲染期间）捕获错误，那么正确处理这些错误就不再那么简单了：渲染期间不允许更新状态。

例如，像这样的简单代码在出错时会导致无限重新渲染循环：

```jsx
const Component = () => {
  const [hasError, setHasError] = useState(false);
  try {
    doSomethingComplicated();
  } catch (e) {
    // 不要这样做！如果出错会导致无限循环
    // 查看下面带有实时示例的代码沙箱
    setHasError(true);
  }
};
```

> 交互式示例和完整代码
> https://advanced-react.com/examples/16/03

当然，我们可以直接在这里返回错误屏幕，而不是设置状态：

```jsx
const Component = () => {
  try {
    doSomethingComplicated();
  } catch (e) {
    // 这是允许的
    return <SomeErrorScreen />;
  }
};
```

但正如你所能想象的，这种方式有点繁琐，并且迫使我们在同一个组件中以不同的方式处理错误：对于 `useEffect` 和回调函数使用状态，而对于其他情况则直接返回。

```jsx
// 虽然这样做可行，但非常繁琐且难以维护，请勿这样做
const SomeComponent = () => {
  const [hasError, setHasError] = useState(false);
  useEffect(() => {
    try {
      // 执行一些操作，比如获取数据
    } catch (e) {
      // 在 useEffect 或回调函数中出现错误时不能直接返回
      // 因此必须使用状态
      setHasError(true);
    }
  });
  try {
    // 在渲染期间执行一些操作
  } catch (e) {
    // 但在这里不能使用状态，因此在出错时必须直接返回
    return <SomeErrorScreen />;
  }
  // 并且在这里仍然需要在错误状态下返回
  if (hasError) return <SomeErrorScreen />;
  return <SomeComponentContent {...datasomething} />;
};
```

总结本节内容：如果我们在 React 中仅仅依赖 `try/catch`，那么我们要么会错过大部分错误，要么会把每个组件都变成一堆难以理解的代码，而这些代码本身可能还会引发错误。

幸运的是，还有另一种方法。

## React 错误边界组件

为了缓解上述限制，React 为我们提供了所谓的“错误边界”[41]：这是一种特殊的 API，它能在某种程度上将普通组件转换为类似 `try/catch` 的语句，不过仅适用于 React 的声明式代码。

你在包括 React 文档在内的所有示例中看到的典型用法大致如下：

```jsx
const Component = () => {
  return (
    <ErrorBoundary>
      <SomeChildComponent />
      <AnotherChildComponent />
    </ErrorBoundary>
  );
};
```

现在，如果在渲染过程中这些组件或它们的子组件中出现问题，错误将被捕获并处理。

但 React 本身并没有为我们提供这个组件，它只是给了我们实现它的工具。最简单的实现方式大概如下：

```jsx
class ErrorBoundary extends React.Component {
  constructor(props) {
    super(props);
    // 初始化错误状态
    this.state = { hasError: false };
  }
  // 如果发生错误，将状态设置为 true
  static getDerivedStateFromError(error) {
    return { hasError: true };
  }
  render() {
    // 如果发生错误，返回一个备用组件
    if (this.state.hasError) {
      return <>Oh no! Epic fail!</>;
    }
    return this.props.children;
  }
}
```

我们创建一个普通的类组件（这里采用传统方式，错误边界目前没有可用的钩子），并实现 `getDerivedStateFromError` 方法 —— 这会将该组件转变为一个合适的错误边界。

处理错误时，另一件重要的事情是将错误信息发送到某个地方，以便唤醒所有值班人员。为此，错误边界为我们提供了 `componentDidCatch` 方法：

```jsx
class ErrorBoundary extends React.Component {
  // 其他部分保持不变
  componentDidCatch(error, errorInfo) {
    // 在此处将错误发送到某个地方
    log(error, errorInfo);
  }
}
```

在错误边界设置完成后，我们可以像使用其他组件一样对其进行任意操作。例如，我们可以让它更具复用性，并将回退组件作为属性传递：

```jsx
render() {
// 如果发生错误，返回一个备用组件
if (this.state.hasError) {
return this.props.fallback;
}
return this.props.children;
}
```

并且可以像这样使用：

```jsx
const Component = () => {
  return (
    <ErrorBoundary fallback={<>Oh no! Do something!</>}>
      <SomeChildComponent />
      <AnotherChildComponent />
    </ErrorBoundary>
  );
};
```

或者其他我们可能需要的功能，比如点击按钮时重置状态、区分不同类型的错误，或者将错误传递到某个上下文环境中。

> 交互式示例和完整代码
> https://advanced-react.com/examples/16/04

不过，在这个看似无错的世界里有一个注意事项：它并不能捕获所有错误。

## 错误边界组件：局限性

错误边界仅能捕获 React 生命周期中发生的错误。而在该生命周期之外发生的事情，例如已解决的 Promise、使用 setTimeout 的异步代码、各种回调函数和事件处理程序，如果没有显式处理，其错误将会消失。

```jsx
const Component = () => {
  useEffect(() => {
    // 这个错误将被 ErrorBoundary 组件捕获
    throw new Error("Destroy everything!");
  }, []);
  const onClick = () => {
    // 这个错误将会消失得无影无踪
    throw new Error("Hulk smash!");
  };
  useEffect(() => {
    // 如果这个请求失败，错误也会消失
    fetch("/bla");
  }, []);
  return <button onClick={onClick}>click me</button>;
};
const ComponentWithBoundary = () => {
  return (
    <ErrorBoundary>
      <Component />
    </ErrorBoundary>
  );
};
```

这里的常见建议是对这些类型的错误使用常规的 try/catch。并且至少在这里我们可以（或多或少）安全地使用状态：事件处理程序的回调函数正是我们通常设置状态的地方。因此从技术上讲，我们可以将两种方法结合起来，做如下操作：

```jsx
const Component = () => {
  const [hasError, setHasError] = useState(false);
  // 此组件及其子组件中的大多数错误将由 ErrorBoundary 捕获
  const onClick = () => {
    try {
      // 这个错误将被 catch 捕获
      throw new Error("Hulk smash!");
    } catch (e) {
      setHasError(true);
    }
  };
  if (hasError) return "something went wrong";
  return <button onClick={onClick}>click me</button>;
};
const ComponentWithBoundary = () => {
  return (
    <ErrorBoundary fallback={"Oh no! Something went wrong"}>
      <Component />
    </ErrorBoundary>
  );
};
```

但是，我们又回到了原点：每个组件都需要维护其“错误”状态，更重要的是，要决定如何处理该状态。

当然，我们可以不在组件层面处理这些错误，而是通过 props 或 Context 将它们向上传播到包含 ErrorBoundary 的父组件。这样一来，至少我们可以在一个地方设置“备用”组件：

```jsx
const Component = ({ onError }) => {
  const onClick = () => {
    try {
      throw new Error("Hulk smash!");
    } catch (e) {
      // 只需调用一个属性，而不是在此维护状态
      onError();
    }
  };
  return <button onClick={onClick}>click me</button>;
};
const ComponentWithBoundary = () => {
  const [hasError, setHasError] = useState();
  const fallback = "Oh no! Something went wrong";
  if (hasError) return fallback;
  return (
    <ErrorBoundary fallback={fallback}>
      <Component onError={() => setHasError(true)} />
    </ErrorBoundary>
  );
};
```

但这会增加大量额外代码！我们必须为渲染树中的每个子组件都这样做。更不用说我们现在基本上要维护两个错误状态了：一个在父组件中，另一个在 `ErrorBoundary` 组件自身中。而且 `ErrorBoundary` 已经具备了将错误向上传播的所有机制，所以我们在这里做了重复的工作。

我们难道不能直接用 `ErrorBoundary` 来捕获异步代码和事件处理程序中的错误吗？

## 使用 ErrorBoundary 捕获异步错误

有趣的是，我们实际上可以使用 `ErrorBoundary` 捕获所有错误！有一个很棒的技巧可以做到这一点[42]。

这个技巧是先用 `try/catch` 捕获这些错误。然后在 `catch` 语句中，触发一次正常的 React 重新渲染，接着将这些错误重新抛回到重新渲染的生命周期中。这样一来，`ErrorBoundary` 就可以像捕获其他错误一样捕获它们。并且由于状态更新是触发重新渲染的方式，而且状态设置函数实际上可以接受一个更新函数[43]作为参数，所以这个解决方案简直妙不可言：

```jsx
const Component = () => {
  // 创建一些随机状态，我们将使用它来抛出错误
  const [state, setState] = useState();
  const onClick = () => {
    try {
      // 发生了一些糟糕的事情
    } catch (e) {
      // 触发状态更新，将更新函数作为参数传入
      setState(() => {
        // 在更新函数中重新抛出这个错误
        // 它将在状态更新期间被触发
        throw e;
      });
    }
  };
};
```

> 交互式示例和完整代码
> https://advanced-react.com/examples/16/05

这里的最后一步是将这个技巧抽象出来，这样我们就无需在每个组件中创建随机状态了。我们可以发挥创意，创建一个钩子，让我们能够抛出异步错误：

```jsx
const useThrowAsyncError = () => {
  const [state, setState] = useState();
  return (error) => {
    setState(() => throw error);
  };
};
```

And use it like this:

```jsx
const Component = () => {
  const throwAsyncError = useThrowAsyncError();
  useEffect(() => {
    fetch("/bla")
      .then()
      .catch((e) => {
        // 在这里抛出异步错误！
        throwAsyncError(e);
      });
  });
};
```

或者，我们可以像这样为回调函数创建一个包装器：

```jsx
const useCallbackWithErrorHandling = (callback) => {
  const [state, setState] = useState();
  return (...args) => {
    try {
      callback(...args);
    } catch (e) {
      setState(() => throw e);
    }
  };
};
```

并像这样使用它：

```jsx
const Component = () => {
  const onClick = () => {
    // do something dangerous here
  };
  const onClickWithErrorHandler = useCallbackWithErrorHandling(onClick);
  return <button onClick={onClickWithErrorHandler}>click me!</button>;
};
```

或者其他你内心期望且应用程序所需的功能。没有任何限制！并且再也不会有错误被遗漏了。

> 交互式示例和完整代码
> https://advanced-react.com/examples/16/06

## 我可以直接使用 react-error-boundary 库吗？

对于那些讨厌重复造轮子，或者更喜欢使用现成解决方案库的人来说，有一个很棒的库叫做 “react-error-boundary”[44]，它实现了一个灵活的 `ErrorBoundary` 组件，并且有一些类似于上述描述的实用工具。
是否使用它仅仅取决于个人偏好、编码风格以及组件内的特殊情况。

## 关键要点

关于错误处理的内容就到此为止了，本章，实际上整本书也到此结束了！希望这对你来说是一次愉快的学习体验。并且不要忘记，在处理 React 中的错误时：

- React 16 版本之后，生命周期中未捕获的错误将会卸载整个应用程序。因此，至少在关键位置放置几个 `ErrorBoundary` 组件是必须的。
- 简单的 `try/catch` 可以很好地捕获回调函数或 Promise 中的错误，但它无法捕获任何嵌套组件中产生的错误，并且你也不能用 `try/catch` 包裹 `useEffect` 或组件的返回值。
- `ErrorBoundary` 组件则相反。它可以捕获渲染树中任何组件产生的错误，但会忽略 Promise 和回调函数（任何异步操作）中的错误。
- 如果我们使用 `try/catch` 捕获异步错误，并将它们重新抛回到正常的 React 生命周期中，就可以将这两种方法结合起来，创建一个超级 `ErrorBoundary` 组件。
- 我们既可以为实现这一点编写一个简单的 `useAsyncError` 钩子，也可以直接使用 `react-error-boundary` 库，它基于类似的原理工作。
